Traceback (most recent call last):
  File "/home/loc/workspace/alkimya.github.io/venv/lib/python3.11/site-packages/jupyter_cache/executors/utils.py", line 58, in single_nb_execution
    executenb(
  File "/home/loc/workspace/alkimya.github.io/venv/lib/python3.11/site-packages/nbclient/client.py", line 1305, in execute
    return NotebookClient(nb=nb, resources=resources, km=km, **kwargs).execute()
           ^^^^^^^^^^^^^^^^^^^^^^^^^^^^^^^^^^^^^^^^^^^^^^^^^^^^^^^^^^^^^^^^^^^^^
  File "/home/loc/workspace/alkimya.github.io/venv/lib/python3.11/site-packages/jupyter_core/utils/__init__.py", line 166, in wrapped
    return loop.run_until_complete(inner)
           ^^^^^^^^^^^^^^^^^^^^^^^^^^^^^^
  File "/usr/lib/python3.11/asyncio/base_events.py", line 653, in run_until_complete
    return future.result()
           ^^^^^^^^^^^^^^^
  File "/home/loc/workspace/alkimya.github.io/venv/lib/python3.11/site-packages/nbclient/client.py", line 705, in async_execute
    await self.async_execute_cell(
  File "/home/loc/workspace/alkimya.github.io/venv/lib/python3.11/site-packages/nbclient/client.py", line 1058, in async_execute_cell
    await self._check_raise_for_error(cell, cell_index, exec_reply)
  File "/home/loc/workspace/alkimya.github.io/venv/lib/python3.11/site-packages/nbclient/client.py", line 914, in _check_raise_for_error
    raise CellExecutionError.from_cell_and_msg(cell, exec_reply_content)
nbclient.exceptions.CellExecutionError: An error occurred while executing the following cell:
------------------
from matplotlib import pyplot as plt
from matplotlib_venn import venn2

v = venn2(subsets={'10': 1, '01': 1, '11': 1}, set_labels=('E', 'F'), set_colors=('b', 'r'), set_alpha=0.5)

v.get_label_by_id('10').set_text('')
v.get_label_by_id('01').set_text('')
v.get_label_by_id('11').set_text('$E \cap F$')

plt.title("Union de E et F")
plt.show()
------------------


[0;31m---------------------------------------------------------------------------[0m
[0;31mTypeError[0m                                 Traceback (most recent call last)
Cell [0;32mIn[5], line 4[0m
[1;32m      1[0m [38;5;28;01mfrom[39;00m [38;5;21;01mmatplotlib[39;00m [38;5;28;01mimport[39;00m pyplot [38;5;28;01mas[39;00m plt
[1;32m      2[0m [38;5;28;01mfrom[39;00m [38;5;21;01mmatplotlib_venn[39;00m [38;5;28;01mimport[39;00m venn2
[0;32m----> 4[0m v [38;5;241m=[39m [43mvenn2[49m[43m([49m[43msubsets[49m[38;5;241;43m=[39;49m[43m{[49m[38;5;124;43m'[39;49m[38;5;124;43m10[39;49m[38;5;124;43m'[39;49m[43m:[49m[43m [49m[38;5;241;43m1[39;49m[43m,[49m[43m [49m[38;5;124;43m'[39;49m[38;5;124;43m01[39;49m[38;5;124;43m'[39;49m[43m:[49m[43m [49m[38;5;241;43m1[39;49m[43m,[49m[43m [49m[38;5;124;43m'[39;49m[38;5;124;43m11[39;49m[38;5;124;43m'[39;49m[43m:[49m[43m [49m[38;5;241;43m1[39;49m[43m}[49m[43m,[49m[43m [49m[43mset_labels[49m[38;5;241;43m=[39;49m[43m([49m[38;5;124;43m'[39;49m[38;5;124;43mE[39;49m[38;5;124;43m'[39;49m[43m,[49m[43m [49m[38;5;124;43m'[39;49m[38;5;124;43mF[39;49m[38;5;124;43m'[39;49m[43m)[49m[43m,[49m[43m [49m[43mset_colors[49m[38;5;241;43m=[39;49m[43m([49m[38;5;124;43m'[39;49m[38;5;124;43mb[39;49m[38;5;124;43m'[39;49m[43m,[49m[43m [49m[38;5;124;43m'[39;49m[38;5;124;43mr[39;49m[38;5;124;43m'[39;49m[43m)[49m[43m,[49m[43m [49m[43mset_alpha[49m[38;5;241;43m=[39;49m[38;5;241;43m0.5[39;49m[43m)[49m
[1;32m      6[0m v[38;5;241m.[39mget_label_by_id([38;5;124m'[39m[38;5;124m10[39m[38;5;124m'[39m)[38;5;241m.[39mset_text([38;5;124m'[39m[38;5;124m'[39m)
[1;32m      7[0m v[38;5;241m.[39mget_label_by_id([38;5;124m'[39m[38;5;124m01[39m[38;5;124m'[39m)[38;5;241m.[39mset_text([38;5;124m'[39m[38;5;124m'[39m)

[0;31mTypeError[0m: venn2() got an unexpected keyword argument 'set_alpha'

